<?xml version="1.0"?>
<robot xmlns:xacro="http://www.ros.org/wiki/xacro">
    <xacro:include filename="inertial_macros.xacro" />
    <material name="white">
        <color rgba="1 1 1 1"/>
    </material>

    <material name="orange">
        <color rgba="1 0.3 0.1 1"/>
    </material>

    <material name="blue">
        <color rgba="0.2 0.2 1 1"/>
    </material>

    <material name="black">
        <color rgba="0 0 0 1"/>
    </material>

    <link name="base_link">
    </link>

    <joint name="chassis_joint" type="fixed">
        <parent link="base_link"/>
        <child link="chassis"/>
        <origin xyz="0 0 0"/>
    </joint>

    <xacro:property name="chassisOrigin" value="0.04 0 0.04" />
    <xacro:property name="chassisLength" value="0.08" />
    <xacro:property name="chassisRadius" value="0.175" />
    <xacro:property name="chassisMaterial" value="white" />
    <link name="chassis">
        <visual>
            <origin xyz="${chassisOrigin}" rpy="0 0 0"/>
            <geometry>
                <cylinder length="${chassisLength}" radius="${chassisRadius}"/>
            </geometry>
            <material name="${chassisMaterial}"/>
        </visual>
        <collision>
            <origin xyz="${chassisOrigin}" rpy="0 0 0"/>
            <geometry>
                <cylinder length="${chassisLength}" radius="${chassisRadius}"/>
            </geometry>
            <material name="${chassisMaterial}"/>       
        </collision>
        <xacro:inertial_box mass="0.5" x="0.3" y="0.3" z="0.15">
            <origin xyz="${chassisOrigin}" rpy="0 0 0"/>
        </xacro:inertial_box>
    </link>

    <!-- LEFT WHEEL -->

    <joint name="left_wheel_joint" type="continuous">
        <parent link="base_link"/>
        <child link="left_wheel"/>
        <origin xyz="0 0.09 0" rpy="-${pi/2} 0 0"/>
        <axis xyz="0 0 1"/>
    </joint>

    <xacro:property name="leftWheelLength" value="0.04" />
    <xacro:property name="leftWheelRadius" value="0.05" />
    <xacro:property name="leftWheelMaterial" value="blue" />
    <link name="left_wheel">
        <visual>
            <geometry>
                <cylinder length="${leftWheelLength}" radius="${leftWheelRadius}" />/>
            </geometry>
            <material name="${leftWheelMaterial}"/>
        </visual>
        <collision>
            <geometry>
                <cylinder length="${leftWheelLength}" radius="${leftWheelRadius}" />/>
            </geometry>
            <material name="${leftWheelMaterial}"/>
        </collision>
        <xacro:inertial_cylinder mass="0.1" length="0.04" radius="0.05">
            <origin xyz="0 0 0" rpy="0 0 0"/>
        </xacro:inertial_cylinder>
    </link>

    <!-- RIGHT WHEEL -->

    <joint name="right_wheel_joint" type="continuous">
        <parent link="base_link"/>
        <child link="right_wheel"/>
        <origin xyz="0 -0.09 0" rpy="${pi/2} 0 0"/>
        <axis xyz="0 0 -1"/>
    </joint>

    <xacro:property name="rightWheelLength" value="0.04" />
    <xacro:property name="rightWheelRadius" value="0.05" />
    <xacro:property name="rightWheelMaterial" value="blue" />
    <link name="right_wheel">
        <visual>
            <geometry>
                <cylinder length="${rightWheelLength}" radius="${rightWheelRadius}" />/>
            </geometry>
            <material name="${rightWheelMaterial}"/>
        </visual>
        <collision>
            <geometry>
                <cylinder length="${rightWheelLength}" radius="${rightWheelRadius}" />/>
            </geometry>
            <material name="${rightWheelMaterial}"/>        
        </collision>  
        <xacro:inertial_cylinder mass="0.1" length="0.04" radius="0.05">
            <origin xyz="0 0 0" rpy="0 0 0"/>
        </xacro:inertial_cylinder>      
    </link>


    <!-- CASTER WHEEL -->

    <joint name="caster_wheel_joint" type="fixed">
        <parent link="chassis"/>
        <child link="caster_wheel"/>
        <origin xyz="0.15 0 0" rpy="0 0 0"/>
    </joint>

    <xacro:property name="casterWheelRadius" value="0.05" />
    <xacro:property name="casterWheelMaterial" value="black" />
    <link name="caster_wheel">
        <visual>
            <geometry>
                <sphere radius="${casterWheelRadius}" />
            </geometry>
            <material name="${casterWheelMaterial}"/>
        </visual>
        <collision>
            <geometry>
                <sphere radius="${casterWheelRadius}" />
            </geometry>
            <material name="${casterWheelMaterial}"/>        
        </collision>   
        <xacro:inertial_sphere mass="0.1" radius="0.05">
            <origin xyz="0 0 0" rpy="0 0 0"/>
        </xacro:inertial_sphere>     
    </link>

</robot>